OrderBookSim/OrderBookSim/Outputs/Log1361470680.txt
0--INFO	Added rule
0--INFO	Added rule
0--INFO	Added rule
0--INFO	Added rule
0--INFO	Added trader: Trader[0]: Cash[$17202.67], Holding:GOOG[14687], PositionCash[$17202.67], PositionHolding:GOOG[14687]
0--INFO	Added trader: Trader[1]: Cash[$8106.94], Holding:GOOG[15854], PositionCash[$8106.94], PositionHolding:GOOG[15854]
0--INFO	Added trader: Trader[2]: Cash[$14943.69], Holding:GOOG[1064], PositionCash[$14943.69], PositionHolding:GOOG[1064]
0--INFO	Added trader: Trader[3]: Cash[$18936.74], Holding:GOOG[12246], PositionCash[$18936.74], PositionHolding:GOOG[12246]
0--INFO	Added trader: Trader[4]: Cash[$4942.17], Holding:GOOG[3472], PositionCash[$4942.17], PositionHolding:GOOG[3472]
0--INFO	Added trader: Trader[5]: Cash[$13748.59], Holding:GOOG[3309], PositionCash[$13748.59], PositionHolding:GOOG[3309]
0--INFO	Added trader: Trader[6]: Cash[$17160.56], Holding:GOOG[7299], PositionCash[$17160.56], PositionHolding:GOOG[7299]
0--INFO	Added trader: Trader[7]: Cash[$7174.90], Holding:GOOG[19045], PositionCash[$7174.90], PositionHolding:GOOG[19045]
0--INFO	Added trader: Trader[8]: Cash[$8077.03], Holding:GOOG[19054], PositionCash[$8077.03], PositionHolding:GOOG[19054]
0--INFO	Added trader: Trader[9]: Cash[$6092.72], Holding:GOOG[4528], PositionCash[$6092.72], PositionHolding:GOOG[4528]
0--INFO	Added trader: Trader[10]: Cash[$12343.52], Holding:GOOG[1948], PositionCash[$12343.52], PositionHolding:GOOG[1948]
0--INFO	Added trader: Trader[11]: Cash[$19649.65], Holding:GOOG[5066], PositionCash[$19649.65], PositionHolding:GOOG[5066]
0--INFO	Added trader: Trader[12]: Cash[$3415.02], Holding:GOOG[2675], PositionCash[$3415.02], PositionHolding:GOOG[2675]
0--INFO	Added trader: Trader[13]: Cash[$16400.04], Holding:GOOG[644], PositionCash[$16400.04], PositionHolding:GOOG[644]
0--INFO	Added trader: Trader[14]: Cash[$9087.19], Holding:GOOG[6600], PositionCash[$9087.19], PositionHolding:GOOG[6600]
0--INFO	Added trader: Trader[15]: Cash[$13368.94], Holding:GOOG[10218], PositionCash[$13368.94], PositionHolding:GOOG[10218]
0--INFO	Added trader: Trader[16]: Cash[$16810.21], Holding:GOOG[11731], PositionCash[$16810.21], PositionHolding:GOOG[11731]
0--INFO	Added trader: Trader[17]: Cash[$343.03], Holding:GOOG[10953], PositionCash[$343.03], PositionHolding:GOOG[10953]
0--INFO	Added trader: Trader[18]: Cash[$4804.22], Holding:GOOG[8421], PositionCash[$4804.22], PositionHolding:GOOG[8421]
0--INFO	Added trader: Trader[19]: Cash[$12099.37], Holding:GOOG[9280], PositionCash[$12099.37], PositionHolding:GOOG[9280]
0--INFO	Added trader: Trader[20]: Cash[$799.58], Holding:GOOG[14334], PositionCash[$799.58], PositionHolding:GOOG[14334]
0--INFO	Added trader: Trader[21]: Cash[$17202.67], Holding:GOOG[14687], PositionCash[$17202.67], PositionHolding:GOOG[14687]
0--INFO	Added trader: Trader[22]: Cash[$17202.67], Holding:GOOG[14687], PositionCash[$17202.67], PositionHolding:GOOG[14687]
0--INFO	Added trader: Trader[23]: Cash[$17202.67], Holding:GOOG[14687], PositionCash[$17202.67], PositionHolding:GOOG[14687]
0--INFO	Added trader: Trader[24]: Cash[$17202.67], Holding:GOOG[14687], PositionCash[$17202.67], PositionHolding:GOOG[14687]
0--INFO	Added trader: Trader[25]: Cash[$17202.67], Holding:GOOG[14687], PositionCash[$17202.67], PositionHolding:GOOG[14687]
0--INFO	Added trader: Trader[26]: Cash[$17202.67], Holding:GOOG[14687], PositionCash[$17202.67], PositionHolding:GOOG[14687]
0--INFO	Added trader: Trader[27]: Cash[$17202.67], Holding:GOOG[14687], PositionCash[$17202.67], PositionHolding:GOOG[14687]
0--INFO	Added trader: Trader[28]: Cash[$17202.67], Holding:GOOG[14687], PositionCash[$17202.67], PositionHolding:GOOG[14687]
0--INFO	Added trader: Trader[29]: Cash[$17202.67], Holding:GOOG[14687], PositionCash[$17202.67], PositionHolding:GOOG[14687]
0--INFO	Added trader: Trader[30]: Cash[$1000000.00], Holding:GOOG[10000000], PositionCash[$1000000.00], PositionHolding:GOOG[10000000]
0--INFO	Added trader: Trader[31]: Cash[$1000000.00], Holding:GOOG[10000000], PositionCash[$1000000.00], PositionHolding:GOOG[10000000]
0--INFO	Added trader: Trader[32]: Cash[$1000000.00], Holding:GOOG[10000000], PositionCash[$1000000.00], PositionHolding:GOOG[10000000]
0--INFO	Added trader: Trader[33]: Cash[$1000000.00], Holding:GOOG[10000000], PositionCash[$1000000.00], PositionHolding:GOOG[10000000]
0--INFO	Added trader: Trader[34]: Cash[$1000000.00], Holding:GOOG[10000000], PositionCash[$1000000.00], PositionHolding:GOOG[10000000]
61--INFO	Enqueued order: Price: 2147483647.00, Volume: 261, Type: BUY, Market Order: 1, Participant: 20, Stock:[ID: 0, Symbol: GOOG], Time: 61, OrderNumber: 0
108--INFO	Enqueued order: Price: 0.00, Volume: 748, Type: SELL, Market Order: 1, Participant: 21, Stock:[ID: 0, Symbol: GOOG], Time: 108, OrderNumber: 1
108--INFO	Enqueued order: Price: 100.09, Volume: 613, Type: SELL, Market Order: 0, Participant: 22, Stock:[ID: 0, Symbol: GOOG], Time: 108, OrderNumber: 2
108--INFO	Enqueued order: Price: 2147483647.00, Volume: 195, Type: BUY, Market Order: 1, Participant: 23, Stock:[ID: 0, Symbol: GOOG], Time: 108, OrderNumber: 3
108--INFO	Enqueued order: Price: 2147483647.00, Volume: 859, Type: BUY, Market Order: 1, Participant: 24, Stock:[ID: 0, Symbol: GOOG], Time: 108, OrderNumber: 4
108--INFO	Enqueued order: Price: 0.00, Volume: 953, Type: SELL, Market Order: 1, Participant: 25, Stock:[ID: 0, Symbol: GOOG], Time: 108, OrderNumber: 5
108--INFO	Enqueued order: Price: 0.00, Volume: 319, Type: SELL, Market Order: 1, Participant: 26, Stock:[ID: 0, Symbol: GOOG], Time: 108, OrderNumber: 6
108--INFO	Enqueued order: Price: 0.00, Volume: 618, Type: SELL, Market Order: 1, Participant: 27, Stock:[ID: 0, Symbol: GOOG], Time: 108, OrderNumber: 7
108--INFO	Enqueued order: Price: 0.00, Volume: 254, Type: SELL, Market Order: 1, Participant: 28, Stock:[ID: 0, Symbol: GOOG], Time: 108, OrderNumber: 8
108--INFO	Enqueued order: Price: 0.00, Volume: 196, Type: SELL, Market Order: 1, Participant: 29, Stock:[ID: 0, Symbol: GOOG], Time: 108, OrderNumber: 9
109--INFO	Last Price Set:100.00
109--INFO	Notified Traders of trade109---Trade ID: 0, Price: 100.00, Volume: 261 between ID:[20] and ID:[21]
111--INFO	Last Price Set:100.00
111--INFO	Notified Traders of trade111---Trade ID: 1, Price: 100.00, Volume: 195 between ID:[23] and ID:[21]
112--INFO	Last Price Set:100.00
112--INFO	Notified Traders of trade112---Trade ID: 2, Price: 100.00, Volume: 292 between ID:[24] and ID:[21]
112--INFO	Last Price Set:100.09
112--INFO	Notified Traders of trade112---Trade ID: 3, Price: 100.09, Volume: 567 between ID:[24] and ID:[22]
122--INFO	Enqueued order: Price: 100.09, Volume: 455, Type: BUY, Market Order: 0, Participant: 20, Stock:[ID: 0, Symbol: GOOG], Time: 122, OrderNumber: 10
123--INFO	Last Price Set:100.09
123--INFO	Notified Traders of trade123---Trade ID: 4, Price: 100.09, Volume: 455 between ID:[20] and ID:[25]
183--INFO	Enqueued order: Price: 0.00, Volume: 511, Type: SELL, Market Order: 1, Participant: 20, Stock:[ID: 0, Symbol: GOOG], Time: 183, OrderNumber: 11
213--INFO	Enqueued order: Price: 100.08, Volume: 64, Type: SELL, Market Order: 0, Participant: 13, Stock:[ID: 0, Symbol: GOOG], Time: 213, OrderNumber: 12
213--INFO	Enqueued order: Price: 100.08, Volume: 660, Type: SELL, Market Order: 0, Participant: 14, Stock:[ID: 0, Symbol: GOOG], Time: 213, OrderNumber: 13
213--INFO	Enqueued order: Price: 100.08, Volume: 1173, Type: SELL, Market Order: 0, Participant: 16, Stock:[ID: 0, Symbol: GOOG], Time: 213, OrderNumber: 14
216--INFO	Enqueued order: Price: 0.00, Volume: 473, Type: SELL, Market Order: 1, Participant: 21, Stock:[ID: 0, Symbol: GOOG], Time: 216, OrderNumber: 15
216--INFO	Enqueued order: Price: 0.00, Volume: 241, Type: SELL, Market Order: 1, Participant: 22, Stock:[ID: 0, Symbol: GOOG], Time: 216, OrderNumber: 16
216--INFO	Enqueued order: Price: 0.00, Volume: 464, Type: SELL, Market Order: 1, Participant: 23, Stock:[ID: 0, Symbol: GOOG], Time: 216, OrderNumber: 17
216--INFO	Enqueued order: Price: 100.16, Volume: 574, Type: SELL, Market Order: 0, Participant: 24, Stock:[ID: 0, Symbol: GOOG], Time: 216, OrderNumber: 18
