OrderBookSim/OrderBookSim/Outputs/Output1361470680.txt
0,100,0,0,0
1,100,0,0,0
2,100,0,0,0
3,100,0,0,0
4,100,0,0,0
5,100,0,0,0
6,100,0,0,0
7,100,0,0,0
8,100,0,0,0
9,100,0,0,0
10,100,0,0,0
11,100,0,0,0
12,100,0,0,0
13,100,0,0,0
14,100,0,0,0
15,100,0,0,0
16,100,0,0,0
17,100,0,0,0
18,100,0,0,0
19,100,0,0,0
20,100,0,0,0
21,100,0,0,0
22,100,0,0,0
23,100,0,0,0
24,100,0,0,0
25,100,0,0,0
26,100,0,0,0
27,100,0,0,0
28,100,0,0,0
29,100,0,0,0
30,100,0,0,0
31,100,0,0,0
32,100,0,0,0
33,100,0,0,0
34,100,0,0,0
35,100,0,0,0
36,100,0,0,0
37,100,0,0,0
38,100,0,0,0
39,100,0,0,0
40,100,0,0,0
41,100,0,0,0
42,100,0,0,0
43,100,0,0,0
44,100,0,0,0
45,100,0,0,0
46,100,0,0,0
47,100,0,0,0
48,100,0,0,0
49,100,0,0,0
50,100,0,0,0
51,100,0,0,0
52,100,0,0,0
53,100,0,0,0
54,100,0,0,0
55,100,0,0,0
56,100,0,0,0
57,100,0,0,0
58,100,0,0,0
59,100,0,0,0
60,100,0,0,0
61,100,0,0,0
62,100,1,0,0
63,100,1,0,0
64,100,1,0,0
65,100,1,0,0
66,100,1,0,0
67,100,1,0,0
68,100,1,0,0
69,100,1,0,0
70,100,1,0,0
71,100,1,0,0
72,100,1,0,0
73,100,1,0,0
74,100,1,0,0
75,100,1,0,0
76,100,1,0,0
77,100,1,0,0
78,100,1,0,0
79,100,1,0,0
80,100,1,0,0
81,100,1,0,0
82,100,1,0,0
83,100,1,0,0
84,100,1,0,0
85,100,1,0,0
86,100,1,0,0
87,100,1,0,0
88,100,1,0,0
89,100,1,0,0
90,100,1,0,0
91,100,1,0,0
92,100,1,0,0
93,100,1,0,0
94,100,1,0,0
95,100,1,0,0
96,100,1,0,0
97,100,1,0,0
98,100,1,0,0
99,100,1,0,0
100,100,1,0,0
101,100,1,0,0
102,100,1,0,0
103,100,1,0,0
104,100,1,0,0
105,100,1,0,0
106,100,1,0,0
107,100,1,0,0
108,100,1,0,0
109,100,0,1,1
110,100,0,2,1
111,100,0,2,2
112,100.09,0,1,4
113,100.09,0,2,4
114,100.09,0,3,4
115,100.09,0,4,4
116,100.09,0,5,4
117,100.09,0,6,4
118,100.09,0,6,4
119,100.09,0,6,4
120,100.09,0,6,4
121,100.09,0,6,4
122,100.09,0,6,4
123,100.09,0,6,5
124,100.09,0,6,5
125,100.09,0,6,5
126,100.09,0,6,5
127,100.09,0,6,5
128,100.09,0,6,5
129,100.09,0,6,5
130,100.09,0,6,5
131,100.09,0,6,5
132,100.09,0,6,5
133,100.09,0,6,5
134,100.09,0,6,5
135,100.09,0,6,5
136,100.09,0,6,5
137,100.09,0,6,5
138,100.09,0,6,5
139,100.09,0,6,5
140,100.09,0,6,5
141,100.09,0,6,5
142,100.09,0,6,5
143,100.09,0,6,5
144,100.09,0,6,5
145,100.09,0,6,5
146,100.09,0,6,5
147,100.09,0,6,5
148,100.09,0,6,5
149,100.09,0,6,5
150,100.09,0,6,5
151,100.09,0,6,5
152,100.09,0,6,5
153,100.09,0,6,5
154,100.09,0,6,5
155,100.09,0,6,5
156,100.09,0,6,5
157,100.09,0,6,5
158,100.09,0,6,5
159,100.09,0,6,5
160,100.09,0,6,5
161,100.09,0,6,5
162,100.09,0,6,5
163,100.09,0,6,5
164,100.09,0,6,5
165,100.09,0,6,5
166,100.09,0,6,5
167,100.09,0,6,5
168,100.09,0,6,5
169,100.09,0,6,5
170,100.09,0,6,5
171,100.09,0,6,5
172,100.09,0,6,5
173,100.09,0,6,5
174,100.09,0,6,5
175,100.09,0,6,5
176,100.09,0,6,5
177,100.09,0,6,5
178,100.09,0,6,5
179,100.09,0,6,5
180,100.09,0,6,5
181,100.09,0,6,5
182,100.09,0,6,5
183,100.09,0,6,5
184,100.09,0,7,5
185,100.09,0,7,5
186,100.09,0,7,5
187,100.09,0,7,5
188,100.09,0,7,5
189,100.09,0,7,5
190,100.09,0,7,5
191,100.09,0,7,5
192,100.09,0,7,5
193,100.09,0,7,5
194,100.09,0,7,5
195,100.09,0,7,5
196,100.09,0,7,5
197,100.09,0,7,5
198,100.09,0,7,5
199,100.09,0,7,5
200,100.09,0,7,5
201,100.09,0,7,5
202,100.09,0,7,5
203,100.09,0,7,5
204,100.09,0,7,5
205,100.09,0,7,5
206,100.09,0,7,5
207,100.09,0,7,5
208,100.09,0,7,5
209,100.09,0,7,5
210,100.09,0,7,5
211,100.09,0,7,5
212,100.09,0,7,5
213,100.09,0,7,5
214,100.09,0,8,5
215,100.09,0,9,5
216,100.09,0,10,5
217,100.09,0,11,5
218,100.09,0,12,5
219,100.09,0,13,5
220,100.09,0,14,5
221,100.09,0,15,5
222,100.09,0,16,5
223,100.09,0,16,6
224,100.09,0,17,6
225,100.09,0,18,6
226,100.09,0,18,6
227,100.09,0,18,6
228,100.09,0,18,6
229,100.09,0,18,6
230,100.09,0,19,6
231,100.09,0,19,6
232,100.09,0,19,6
233,100.09,0,19,6
234,100.09,0,19,6
235,100.09,0,19,6
236,100.09,0,19,6
237,100.09,0,19,6
238,100.09,0,19,6
239,100.09,0,19,6
240,100.09,0,19,6
241,100.09,0,19,6
242,100.09,0,19,6
243,100.09,0,19,6
244,100.09,0,20,6
245,100.09,0,21,6
246,100.09,0,21,6
247,100.09,0,21,6
248,100.09,0,21,6
249,100.09,0,21,6
250,100.09,0,21,6
251,100.09,0,21,6
252,100.09,0,21,6
253,100.09,0,21,6
254,100.09,0,21,6
255,100.09,0,21,6
256,100.09,0,21,6
257,100.09,0,21,6
258,100.09,0,21,6
259,100.09,0,21,6
260,100.09,0,21,6
261,100.09,0,21,6
262,100.09,0,21,6
263,100.09,0,22,6
264,100.09,0,22,6
265,100.09,0,22,6
266,100.09,0,22,6
267,100.09,0,22,6
268,100.09,0,22,6
269,100.09,0,22,6
270,100.09,0,22,6
271,100.09,0,22,6
272,100.09,0,22,6
273,100.09,0,22,6
274,100.09,0,23,6
275,100.09,0,23,6
276,100.09,0,23,6
277,100.09,0,23,6
278,100.09,0,23,6
279,100.09,0,23,6
280,100.09,0,23,6
281,100.09,0,23,6
282,100.09,0,23,6
283,100.09,0,23,6
284,100.09,0,23,6
285,100.09,0,23,6
286,100.09,0,23,6
287,100.09,0,24,6
288,100.09,0,24,6
289,100.09,0,24,6
290,100.09,0,24,6
291,100.09,0,24,6
292,100.09,0,24,6
293,100.09,0,24,6
294,100.09,0,24,6
295,100.09,0,24,6
296,100.09,0,24,6
297,100.09,0,24,6
298,100.09,0,24,6
299,100.09,0,24,6
300,100.09,0,24,6
301,100.09,0,24,6
302,100.09,0,24,6
303,100.09,0,24,6
304,100.09,0,24,6
305,100.09,0,24,6
306,100.09,0,22,9
307,100.09,0,23,9
308,100.09,0,23,9
309,100.09,0,23,9
310,100.09,0,23,9
311,100.09,0,23,9
312,100.09,0,23,9
313,100.09,0,23,9
314,100.09,0,23,9
315,100.09,0,23,9
316,100.09,0,23,9
317,100.09,0,23,9
318,100.09,0,23,9
319,100.09,0,23,9
320,100.09,0,23,9
321,100.09,0,23,9
322,100.09,0,23,9
323,100.09,0,23,9
324,100.09,0,23,9
325,100.09,0,24,9
326,100.09,0,25,9
327,100.09,0,25,10
328,100.09,0,26,10
329,100.09,0,23,14
330,100.09,0,22,16
331,100.09,0,21,18
332,100.09,0,22,18
333,100.09,0,21,20
334,100.09,0,21,20
335,100.09,0,21,20
336,100.09,0,21,20
337,100.09,0,21,20
338,100.09,0,21,20
339,100.09,0,21,20
340,100.09,0,21,20
341,100.09,0,21,20
342,100.09,0,21,20
343,100.09,0,21,20
344,100.09,0,21,20
345,100.09,0,21,20
346,100.09,0,21,20
347,100.09,0,21,20
348,100.09,0,21,20
349,100.09,0,21,20
350,100.09,0,21,20
351,100.09,0,21,20
352,100.09,0,21,20
353,100.09,0,21,20
354,100.09,0,21,20
355,100.09,0,21,20
356,100.09,0,21,20
357,100.09,0,22,20
358,100.09,0,22,20
359,100.09,0,22,20
360,100.09,0,22,20
361,100.09,0,22,20
362,100.09,0,23,20
363,100.09,0,23,20
364,100.09,0,23,20
365,100.09,0,23,20
366,100.09,0,23,20
367,100.09,0,22,22
368,100.09,0,22,22
369,100.09,0,22,22
370,100.09,0,22,22
371,100.09,0,22,22
372,100.09,0,22,22
373,100.09,0,22,22
374,100.09,0,22,22
375,100.09,0,22,22
376,100.09,0,22,22
377,100.09,0,22,22
378,100.09,0,22,22
379,100.09,0,22,22
380,100.09,0,22,22
381,100.09,0,22,22
382,100.09,0,22,22
383,100.09,0,22,22
384,100.09,0,22,22
385,100.09,0,22,22
386,100.09,0,22,22
387,100.09,0,23,22
388,100.09,0,23,22
389,100.09,0,23,22
390,100.09,0,23,22
391,100.09,0,23,22
392,100.09,0,23,22
393,100.09,0,23,22
394,100.09,0,23,22
395,100.09,0,23,22
396,100.09,0,23,22
397,100.09,0,23,22
398,100.09,0,23,22
399,100.09,0,23,22
400,100.09,0,23,22
401,100.09,0,23,22
402,100.09,0,23,22
403,100.09,0,23,22
404,100.09,0,23,22
405,100.09,0,23,22
406,100.09,0,23,22
407,100.09,0,23,22
408,100.09,0,23,22
409,100.09,0,23,22
410,100.09,0,23,22
411,100.09,0,24,22
412,100.09,0,24,22
413,100.09,0,24,22
414,100.09,0,24,22
415,100.09,0,24,22
416,100.09,0,24,22
417,100.09,0,24,22
418,100.09,0,24,22
419,100.09,0,24,22
420,100.09,0,24,22
421,100.09,0,24,22
422,100.09,0,24,22
423,100.09,0,24,22
424,100.09,0,24,22
425,100.09,0,24,22
426,100.09,0,24,22
427,100.09,0,24,22
428,100.09,0,25,22
429,100.09,0,25,22
430,100.09,0,25,22
431,100.09,0,25,22
432,100.09,0,25,22
433,100.09,0,24,24
434,100.09,0,25,24
435,100.09,0,24,26
436,100.09,0,25,26
437,100.01,0,25,27
438,100.01,0,26,27
439,100.01,0,23,31
440,100.01,0,23,32
441,100.01,0,24,32
442,100.01,0,24,32
443,100.01,0,24,32
444,100.01,0,24,32
445,100.01,0,24,32
446,100.01,0,24,32
447,100.01,0,24,32
448,100.01,0,24,32
449,100.01,0,24,32
450,100.01,0,24,32
451,100.08,0,7,50
452,100.16,1,0,57
453,100.16,0,1,58
454,100.16,1,0,59
455,100.16,0,1,60
456,100.16,0,1,60
457,100.16,0,1,60
458,100.16,0,1,60
459,100.15,0,1,61
460,100.15,0,1,61
461,100.15,0,1,61
462,100.15,0,1,61
463,100.15,0,1,61
464,100.15,0,1,61
465,100.15,0,1,61
466,100.15,0,1,61
467,100.15,0,1,61
468,100.15,0,1,61
469,100.15,0,1,61
470,100.15,0,1,61
471,100.15,0,1,61
472,100.15,0,1,61
473,100.15,0,1,61
474,100.15,0,1,61
